

<mujoco>
  <compiler meshdir="assets/meshes" texturedir="assets/textures" autolimits="true"/>
 
  <asset>
    
       
                      
  </asset>

  <default>
    
        <!-- RevolvingDoor -->
        <default class="revolvingDoor">
          <geom   type="box" size="0.001 0.02 0.01"  />
        </default>
      
  </default>


  <worldbody>
    
        <body pos="0 0 0.01" euler="0 0 0">
          <joint type="hinge" axis="0 1 0"/>
          <geom class="revolvingDoor" />
          <geom type="cylinder" size="0.001 0.015"/>

        </body>
      
  </worldbody>

 
</mujoco>
