

<mujoco>
  <compiler meshdir="assets/meshes" texturedir="assets/textures" autolimits="true"/>
 

  <asset>
    <!-- light  -->
    <texture type="skybox" builtin="gradient" rgb1=".3 .5 .7" rgb2="0 0 0" width="32" height="512"/>
    <!-- floor  -->
    <texture  name="grid" type="2d" builtin="checker" width="512" height="512" rgb1=".1 .2 .3" rgb2=".2 .3 .4"/>
    <material name="grid" texture="grid" texrepeat="1 1" texuniform="true" reflectance=".2"/>

  </asset>

  <default>

    
        <!-- Domino -->
        <default class="domino">
          <geom   type="box"  friction="1" />
        </default>
      
    
        <!-- Ball -->
        <default class="seasaw_mount">
          <geom  type="box" size="0.01 0.01 0.03"/>
        </default>
      
    
        <!-- Ball -->
        <default class="ball">
          <geom   type="sphere"   />
        </default>
      
    
        <!-- Box -->
        <default class="Box">
          <geom   type="box"  friction="1" />
        </default>
      
   
  </default>


  <worldbody>
    <light name="spotlight" mode="targetbodycom" target="seasaw" diffuse=".8 .8 .8" specular="0.3 0.3 0.3" pos="0 -6 4" cutoff="30"/>
    <!-- floor  -->
    <geom  type="plane" size="3 3 .01" material="grid"/>
    <!-- camera  -->
    <body pos="0 0 1" >
      <camera name="traking_camera"  mode="targetbody"/>
    </body>
  
    
        <body pos="0.25 -0.35 0.02" euler="0 0 0">
          <joint type="free" />
          <geom class="ball" size="0.02" rgba="0.65625 0.8125 0.55078125 1"/>
        </body>
      
    
		 
        <body pos="0.26 -0.3 0.03" euler="0 0 -90.0">
       
          
      <joint type="free"   />
    
          <geom class="domino" size="0.0015 0.015 0.03" rgba="0.99609375 0.42578125 0.4140625 1"/>
        </body>
      
		 
        <body pos="0.26 -0.27 0.04" euler="0 0 -81.0">
       
          
      <joint type="free"   />
    
          <geom class="domino" size="0.002 0.02 0.04" rgba="0.93359375 0.7421875 0.48828125 1"/>
        </body>
      
		 
        <body pos="0.25 -0.24 0.05" euler="0 0 -72.0">
       
          
      <joint type="free"   />
    
          <geom class="domino" size="0.0025 0.025 0.05" rgba="0.91015625 0.921875 0.41796875 1"/>
        </body>
      
		 
        <body pos="0.24 -0.21 0.06" euler="0 0 -63.0">
       
          
      <joint type="free"   />
    
          <geom class="domino" size="0.003 0.03 0.06" rgba="0.54296875 0.82421875 0.8984375 1"/>
        </body>
      
		 
        <body pos="0.22 -0.18 0.07" euler="0 0 -54.0">
       
          
      <joint type="free"   />
    
          <geom class="domino" size="0.0035 0.035 0.07" rgba="0.91015625 0.80078125 0.8125 1"/>
        </body>
      
		 
        <body pos="0.2 -0.16 0.08" euler="0 0 -45.0">
       
          
      <joint type="free"   />
    
          <geom class="domino" size="0.004 0.04 0.08" rgba="0.69140625 0.6328125 0.7890625 1"/>
        </body>
      
		 
        <body pos="0.18 -0.14 0.09" euler="0 0 -36.0">
       
          
      <joint type="free"   />
    
          <geom class="domino" size="0.0045 0.045 0.09" rgba="0.99609375 0.42578125 0.4140625 1"/>
        </body>
      
		 
        <body pos="0.15 -0.12 0.1" euler="0 0 -27.0">
       
          
      <joint type="free"   />
    
          <geom class="domino" size="0.005 0.05 0.1" rgba="0.93359375 0.7421875 0.48828125 1"/>
        </body>
      
		 
        <body pos="0.12 -0.11 0.11" euler="0 0 -18.0">
       
          
      <joint type="free"   />
    
          <geom class="domino" size="0.0055 0.055 0.11" rgba="0.91015625 0.921875 0.41796875 1"/>
        </body>
      
		 
        <body pos="0.09 -0.1 0.12" euler="0 0 -9.0">
       
          
      <joint type="free"   />
    
          <geom class="domino" size="0.006 0.06 0.12" rgba="0.54296875 0.82421875 0.8984375 1"/>
        </body>
      
    
        <body name="seasaw" pos="-0.2 0.0 0" euler="0 0 0">
          
		<geom class="seasaw_mount" pos="0 0.05 0" rgba="0.5 0.0 0.0 1"/>
		<geom class="seasaw_mount" pos="0 -0.05 0" rgba="0.5 0.0 0.0 1"/>
      <body>
        
    <joint type="hinge"  axis="0 1 0"  pos= "0 0 0.02"    />
  
        <geom type="cylinder" size="0.005 0.05" pos="0 0 0.02" euler="90 0 0" rgba="0.84765625 0.15234375 0.3359375 1"/>
        <geom type="box" size="0.1 0.02 0.005" pos="0 0 0.03" friction="1" mass="0.1" rgba="0.84765625 0.15234375 0.3359375 1"/>
      </body>
    
        </body>
      
    
        <body pos="-0.28 0.0 0.05" euler="0 0 0" >
         
          <joint type="free" />
          <geom class="Box" size="0.01 0.01 0.01" mass="0.01" rgba="0.0 0.70703125 0.796875 1"/>
        </body>
      
   
  </worldbody>


  <keyframe>
    <key name="one" qvel="0 1 0 0 0 0 0 0 0 0 0 0 0 0 0 0 0 0 0 0 0 0 0 0 0 0 0 0 0 0 0 0 0 0 0 0 0 0 0 0 0 0 0 0 0 0 0 0 0 0 0 0 0 0 0 0 0 0 0 0 0 0 0 0 0 0 0 0 0 0 0 0 0" />
  </keyframe>


 
</mujoco>